<?xml version="1.0"?>

<robot name="Robot1">		
	<link name="link_chassis">
    <!-- body -->
    <visual>
      <origin rpy="0 0 0" xyz="0 0 0"/>
      <geometry>
        <box size="0.5 0.3 0.07"/>
      </geometry>
    </visual>
    <!-- caster front -->
    <visual name="caster_front_visual">
      <origin rpy=" 0 0 0" xyz="0.2 0 -0.05"/>
      <geometry>
        <sphere radius="0.05"/>
      </geometry>
    </visual>
  </link>

   <link name="link_right_wheel">
    <visual name="link_right_wheel_visual">
      <origin rpy="0 1.5707 1.5707" xyz="0 0 0"/>
      <geometry>
       	<cylinder length="0.04" radius="0.1"/>
      </geometry>
    </visual>
  </link>

   <link name="link_left_wheel">
    <visual name="link_left_wheel_visual">
      <origin rpy="0 1.5707 1.5707" xyz="0 0 0"/>
      <geometry>
        <cylinder length="0.04" radius="0.1"/>
      </geometry>
    </visual>
  </link>

   <link name="link_rotating_base">
    <visual name="link_rotating_base_visual">
      <origin rpy="0 0 0" xyz="0 0 0.02"/>
      <geometry>
        <box size="0.1 0.1 0.1"/>
      </geometry>
    </visual>
  </link>

  <joint name="joint_rotating_base" type="continuous">
    <origin rpy="0 0 0" xyz="0 0 0.065"/>
    <child link="link_rotating_base"/>
    <parent link="link_chassis"/>
    <axis rpy="0 0 0" xyz="0 0 1"/>
    <limit effort="10000" velocity="1000"/>
    <joint_properties damping="1.0" friction="1.0"/>
  </joint>
  
   <link name="link_first_arm">
    <visual name="link_first_arm_visual">
      <origin rpy="0 0 0" xyz="0 0 0.25"/>
      <geometry>
        <box size="0.07 0.07 0.5"/>
      </geometry>
    </visual>
  </link>

  <joint name="joint_link_first_arm" type="revolute">
    <origin rpy="0 0 0" xyz="0 0 0.07"/>
    <child link="link_first_arm"/>
    <parent link="link_rotating_base"/>
    <axis xyz="1 0 0"/>
    <limit effort="10000" lower="-0.548" upper="0.548" velocity="1000"/>
    <joint_properties damping="1.0" friction="1.0"/>
  </joint>
 
    <link name="link_second_arm">
    <visual name="link_second_arm_visual">
      <origin rpy="0 0 0" xyz="0 0 0.25"/>
      <geometry>
        <box size="0.07 0.07 0.5"/>
      </geometry>
    </visual>
  </link>

  <joint name="joint_link_second_arm" type="revolute">
    <origin rpy="0 0 0" xyz="0.075 0 0.35"/>
    <child link="link_second_arm"/>
    <parent link="link_first_arm"/>
    <axis xyz="1 0 0"/>
    <limit effort="10000" lower="-0.548" upper="0.548" velocity="1000"/>
    <joint_properties damping="1.0" friction="1.0"/>
  </joint>
  
  <joint name="joint_right_wheel" type="continuous">
    <origin rpy="0 0 0" xyz="-0.05 0.15 0"/>
    <child link="link_right_wheel"/>
    <parent link="link_chassis"/>
    <axis rpy="0 0 0" xyz="0 1 0"/>
    <limit effort="10000" velocity="1000"/>
    <joint_properties damping="1.0" friction="1.0"/>
  </joint>
  
  
  <joint name="joint_left_wheel" type="continuous">
    <origin rpy="0 0 0" xyz="-0.05 -0.15 0"/>
    <child link="link_left_wheel"/>
    <parent link="link_chassis"/>
    <axis rpy="0 0 0" xyz="0 1 0"/>
    <limit effort="10000" velocity="1000"/>
    <joint_properties damping="1.0" friction="1.0"/>
  </joint>

</robot>
